which: no fi_info in (/mnt/petrelfs/zhangdi1/.vscode-server/cli/servers/Stable-5437499feb04f7a586f677b155b039bc2b3669eb/server/bin/remote-cli:/mnt/petrelfs/zhangdi1/miniforge3/envs/internvl/bin:/mnt/petrelfs/zhangdi1/miniforge3/condabin:/usr/local/bin:/usr/bin:/usr/local/sbin:/usr/sbin:/mnt/petrelfs/zhangdi1/.local/bin:/mnt/petrelfs/zhangdi1/bin)
2024-07-03 15:51:44 | INFO | gradio_web_server | args: Namespace(host='0.0.0.0', port=10058, controller_url='http://10.140.24.69:10050', concurrency_count=10, model_list_mode='reload', share=False, moderate=False, embed=False)
2024-07-03 15:51:44 | INFO | gradio_web_server | Models: ['chemvlm']
2024-07-03 15:51:44 | INFO | gradio_web_server | Namespace(host='0.0.0.0', port=10058, controller_url='http://10.140.24.69:10050', concurrency_count=10, model_list_mode='reload', share=False, moderate=False, embed=False)
2024-07-03 15:52:09 | INFO | stdout | Running on local URL:  http://0.0.0.0:10058
2024-07-03 15:52:09 | INFO | stdout | 
2024-07-03 15:52:09 | INFO | stdout | To create a public link, set `share=True` in `launch()`.
2024-07-03 15:52:10 | INFO | httpx | HTTP Request: POST http://localhost:10058/reset "HTTP/1.1 200 OK"
2024-07-03 15:52:27 | ERROR | asyncio | Task exception was never retrieved
future: <Task finished name='mtwdxhbx1bq_11' coro=<Queue.process_events() done, defined at /mnt/petrelfs/zhangdi1/miniforge3/envs/internvl/lib/python3.11/site-packages/gradio/queueing.py:342> exception=1 validation error for PredictBody
event_id
  Field required [type=missing, input_value={'data': [], 'event_data'...on_hash': 'mtwdxhbx1bq'}, input_type=dict]
    For further information visit https://errors.pydantic.dev/2.8/v/missing>
Traceback (most recent call last):
  File "/mnt/petrelfs/zhangdi1/miniforge3/envs/internvl/lib/python3.11/site-packages/gradio/queueing.py", line 346, in process_events
    client_awake = await self.gather_event_data(event)
                   ^^^^^^^^^^^^^^^^^^^^^^^^^^^^^^^^^^^
  File "/mnt/petrelfs/zhangdi1/miniforge3/envs/internvl/lib/python3.11/site-packages/gradio/queueing.py", line 219, in gather_event_data
    data, client_awake = await self.get_message(event, timeout=receive_timeout)
                         ^^^^^^^^^^^^^^^^^^^^^^^^^^^^^^^^^^^^^^^^^^^^^^^^^^^^^^
  File "/mnt/petrelfs/zhangdi1/miniforge3/envs/internvl/lib/python3.11/site-packages/gradio/queueing.py", line 448, in get_message
    return PredictBody(**data), True
           ^^^^^^^^^^^^^^^^^^^
  File "/mnt/petrelfs/zhangdi1/miniforge3/envs/internvl/lib/python3.11/site-packages/pydantic/main.py", line 192, in __init__
    self.__pydantic_validator__.validate_python(data, self_instance=self)
pydantic_core._pydantic_core.ValidationError: 1 validation error for PredictBody
event_id
  Field required [type=missing, input_value={'data': [], 'event_data'...on_hash': 'mtwdxhbx1bq'}, input_type=dict]
    For further information visit https://errors.pydantic.dev/2.8/v/missing
2024-07-03 15:52:27 | INFO | httpx | HTTP Request: POST http://localhost:10058/reset "HTTP/1.1 200 OK"
slurmstepd: error: *** JOB 3648122 ON SH-IDC1-10-140-24-69 CANCELLED AT 2024-07-08T15:21:05 ***
