2024-06-05 16:14:50 | INFO | gradio_web_server | args: Namespace(host='0.0.0.0', port=10055, controller_url='http://10.140.24.63:10050', concurrency_count=10, model_list_mode='reload', share=False, moderate=False, embed=False)
2024-06-05 16:14:50 | INFO | gradio_web_server | Models: ['6.5']
2024-06-05 16:14:50 | INFO | gradio_web_server | Namespace(host='0.0.0.0', port=10055, controller_url='http://10.140.24.63:10050', concurrency_count=10, model_list_mode='reload', share=False, moderate=False, embed=False)
2024-06-05 16:15:12 | INFO | stdout | Running on local URL:  http://0.0.0.0:10055
2024-06-05 16:15:12 | INFO | stdout | 
2024-06-05 16:15:12 | INFO | stdout | To create a public link, set `share=True` in `launch()`.
2024-06-05 16:16:16 | ERROR | asyncio | Task exception was never retrieved
future: <Task finished name='332i8ub3sjh_11' coro=<Queue.process_events() done, defined at /mnt/petrelfs/zhangdi1/miniforge3/envs/internvl/lib/python3.9/site-packages/gradio/queueing.py:342> exception=1 validation error for PredictBody
event_id
  Field required [type=missing, input_value={'data': [], 'event_data'...on_hash': '332i8ub3sjh'}, input_type=dict]
    For further information visit https://errors.pydantic.dev/2.7/v/missing>
Traceback (most recent call last):
  File "/mnt/petrelfs/zhangdi1/miniforge3/envs/internvl/lib/python3.9/site-packages/gradio/queueing.py", line 346, in process_events
    client_awake = await self.gather_event_data(event)
  File "/mnt/petrelfs/zhangdi1/miniforge3/envs/internvl/lib/python3.9/site-packages/gradio/queueing.py", line 219, in gather_event_data
    data, client_awake = await self.get_message(event, timeout=receive_timeout)
  File "/mnt/petrelfs/zhangdi1/miniforge3/envs/internvl/lib/python3.9/site-packages/gradio/queueing.py", line 448, in get_message
    return PredictBody(**data), True
  File "/mnt/petrelfs/zhangdi1/miniforge3/envs/internvl/lib/python3.9/site-packages/pydantic/main.py", line 176, in __init__
    self.__pydantic_validator__.validate_python(data, self_instance=self)
pydantic_core._pydantic_core.ValidationError: 1 validation error for PredictBody
event_id
  Field required [type=missing, input_value={'data': [], 'event_data'...on_hash': '332i8ub3sjh'}, input_type=dict]
    For further information visit https://errors.pydantic.dev/2.7/v/missing
2024-06-05 16:18:23 | ERROR | asyncio | Task exception was never retrieved
future: <Task finished name='2lj7aejtft2_11' coro=<Queue.process_events() done, defined at /mnt/petrelfs/zhangdi1/miniforge3/envs/internvl/lib/python3.9/site-packages/gradio/queueing.py:342> exception=1 validation error for PredictBody
event_id
  Field required [type=missing, input_value={'data': [], 'event_data'...on_hash': '2lj7aejtft2'}, input_type=dict]
    For further information visit https://errors.pydantic.dev/2.7/v/missing>
Traceback (most recent call last):
  File "/mnt/petrelfs/zhangdi1/miniforge3/envs/internvl/lib/python3.9/site-packages/gradio/queueing.py", line 346, in process_events
    client_awake = await self.gather_event_data(event)
  File "/mnt/petrelfs/zhangdi1/miniforge3/envs/internvl/lib/python3.9/site-packages/gradio/queueing.py", line 219, in gather_event_data
    data, client_awake = await self.get_message(event, timeout=receive_timeout)
  File "/mnt/petrelfs/zhangdi1/miniforge3/envs/internvl/lib/python3.9/site-packages/gradio/queueing.py", line 448, in get_message
    return PredictBody(**data), True
  File "/mnt/petrelfs/zhangdi1/miniforge3/envs/internvl/lib/python3.9/site-packages/pydantic/main.py", line 176, in __init__
    self.__pydantic_validator__.validate_python(data, self_instance=self)
pydantic_core._pydantic_core.ValidationError: 1 validation error for PredictBody
event_id
  Field required [type=missing, input_value={'data': [], 'event_data'...on_hash': '2lj7aejtft2'}, input_type=dict]
    For further information visit https://errors.pydantic.dev/2.7/v/missing
slurmstepd: error: *** JOB 3528954 ON SH-IDC1-10-140-24-63 CANCELLED AT 2024-06-05T17:32:47 ***
