2024-06-05 16:00:06 | INFO | gradio_web_server | args: Namespace(host='0.0.0.0', port=10055, controller_url='http://10.140.24.63:10050', concurrency_count=10, model_list_mode='reload', share=False, moderate=False, embed=False)
2024-06-05 16:00:06 | INFO | gradio_web_server | Models: []
2024-06-05 16:00:06 | INFO | gradio_web_server | Namespace(host='0.0.0.0', port=10055, controller_url='http://10.140.24.63:10050', concurrency_count=10, model_list_mode='reload', share=False, moderate=False, embed=False)
2024-06-05 16:00:24 | INFO | botocore.credentials | Found credentials in shared credentials file: ~/.aws/credentials
2024-06-05 16:01:02 | ERROR | asyncio | Task exception was never retrieved
future: <Task finished name='0fw58q7ueio4_11' coro=<Queue.process_events() done, defined at /mnt/petrelfs/zhangdi1/miniforge3/envs/internvl/lib/python3.9/site-packages/gradio/queueing.py:342> exception=1 validation error for PredictBody
event_id
  Field required [type=missing, input_value={'data': [], 'event_data'...n_hash': '0fw58q7ueio4'}, input_type=dict]
    For further information visit https://errors.pydantic.dev/2.7/v/missing>
Traceback (most recent call last):
  File "/mnt/petrelfs/zhangdi1/miniforge3/envs/internvl/lib/python3.9/site-packages/gradio/queueing.py", line 346, in process_events
    client_awake = await self.gather_event_data(event)
  File "/mnt/petrelfs/zhangdi1/miniforge3/envs/internvl/lib/python3.9/site-packages/gradio/queueing.py", line 219, in gather_event_data
    data, client_awake = await self.get_message(event, timeout=receive_timeout)
  File "/mnt/petrelfs/zhangdi1/miniforge3/envs/internvl/lib/python3.9/site-packages/gradio/queueing.py", line 448, in get_message
    return PredictBody(**data), True
  File "/mnt/petrelfs/zhangdi1/miniforge3/envs/internvl/lib/python3.9/site-packages/pydantic/main.py", line 176, in __init__
    self.__pydantic_validator__.validate_python(data, self_instance=self)
pydantic_core._pydantic_core.ValidationError: 1 validation error for PredictBody
event_id
  Field required [type=missing, input_value={'data': [], 'event_data'...n_hash': '0fw58q7ueio4'}, input_type=dict]
    For further information visit https://errors.pydantic.dev/2.7/v/missing
slurmstepd: error: *** JOB 3528928 ON SH-IDC1-10-140-24-63 CANCELLED AT 2024-06-05T16:02:04 ***
