2024-06-05 15:39:41 | INFO | gradio_web_server | args: Namespace(host='0.0.0.0', port=10051, controller_url='http://10.140.24.69:10050', concurrency_count=10, model_list_mode='reload', share=False, moderate=False, embed=False)
2024-06-05 15:39:41 | INFO | gradio_web_server | Models: ['6.5']
2024-06-05 15:39:41 | INFO | gradio_web_server | Namespace(host='0.0.0.0', port=10051, controller_url='http://10.140.24.69:10050', concurrency_count=10, model_list_mode='reload', share=False, moderate=False, embed=False)
2024-06-05 15:40:00 | INFO | botocore.credentials | Found credentials in shared credentials file: ~/.aws/credentials
2024-06-05 15:41:01 | ERROR | asyncio | Task exception was never retrieved
future: <Task finished name='k8jdj1r8hr_11' coro=<Queue.process_events() done, defined at /mnt/petrelfs/zhangdi1/miniforge3/envs/internvl/lib/python3.9/site-packages/gradio/queueing.py:342> exception=1 validation error for PredictBody
event_id
  Field required [type=missing, input_value={'data': [], 'event_data'...ion_hash': 'k8jdj1r8hr'}, input_type=dict]
    For further information visit https://errors.pydantic.dev/2.7/v/missing>
Traceback (most recent call last):
  File "/mnt/petrelfs/zhangdi1/miniforge3/envs/internvl/lib/python3.9/site-packages/gradio/queueing.py", line 346, in process_events
    client_awake = await self.gather_event_data(event)
  File "/mnt/petrelfs/zhangdi1/miniforge3/envs/internvl/lib/python3.9/site-packages/gradio/queueing.py", line 219, in gather_event_data
    data, client_awake = await self.get_message(event, timeout=receive_timeout)
  File "/mnt/petrelfs/zhangdi1/miniforge3/envs/internvl/lib/python3.9/site-packages/gradio/queueing.py", line 448, in get_message
    return PredictBody(**data), True
  File "/mnt/petrelfs/zhangdi1/miniforge3/envs/internvl/lib/python3.9/site-packages/pydantic/main.py", line 176, in __init__
    self.__pydantic_validator__.validate_python(data, self_instance=self)
pydantic_core._pydantic_core.ValidationError: 1 validation error for PredictBody
event_id
  Field required [type=missing, input_value={'data': [], 'event_data'...ion_hash': 'k8jdj1r8hr'}, input_type=dict]
    For further information visit https://errors.pydantic.dev/2.7/v/missing
2024-06-05 15:41:37 | ERROR | asyncio | Task exception was never retrieved
future: <Task finished name='pv7t1wufbrh_11' coro=<Queue.process_events() done, defined at /mnt/petrelfs/zhangdi1/miniforge3/envs/internvl/lib/python3.9/site-packages/gradio/queueing.py:342> exception=1 validation error for PredictBody
event_id
  Field required [type=missing, input_value={'data': [], 'event_data'...on_hash': 'pv7t1wufbrh'}, input_type=dict]
    For further information visit https://errors.pydantic.dev/2.7/v/missing>
Traceback (most recent call last):
  File "/mnt/petrelfs/zhangdi1/miniforge3/envs/internvl/lib/python3.9/site-packages/gradio/queueing.py", line 346, in process_events
    client_awake = await self.gather_event_data(event)
  File "/mnt/petrelfs/zhangdi1/miniforge3/envs/internvl/lib/python3.9/site-packages/gradio/queueing.py", line 219, in gather_event_data
    data, client_awake = await self.get_message(event, timeout=receive_timeout)
  File "/mnt/petrelfs/zhangdi1/miniforge3/envs/internvl/lib/python3.9/site-packages/gradio/queueing.py", line 448, in get_message
    return PredictBody(**data), True
  File "/mnt/petrelfs/zhangdi1/miniforge3/envs/internvl/lib/python3.9/site-packages/pydantic/main.py", line 176, in __init__
    self.__pydantic_validator__.validate_python(data, self_instance=self)
pydantic_core._pydantic_core.ValidationError: 1 validation error for PredictBody
event_id
  Field required [type=missing, input_value={'data': [], 'event_data'...on_hash': 'pv7t1wufbrh'}, input_type=dict]
    For further information visit https://errors.pydantic.dev/2.7/v/missing
2024-06-05 15:41:54 | ERROR | asyncio | Task exception was never retrieved
future: <Task finished name='k99p9mnm1he_11' coro=<Queue.process_events() done, defined at /mnt/petrelfs/zhangdi1/miniforge3/envs/internvl/lib/python3.9/site-packages/gradio/queueing.py:342> exception=1 validation error for PredictBody
event_id
  Field required [type=missing, input_value={'data': [], 'event_data'...on_hash': 'k99p9mnm1he'}, input_type=dict]
    For further information visit https://errors.pydantic.dev/2.7/v/missing>
Traceback (most recent call last):
  File "/mnt/petrelfs/zhangdi1/miniforge3/envs/internvl/lib/python3.9/site-packages/gradio/queueing.py", line 346, in process_events
    client_awake = await self.gather_event_data(event)
  File "/mnt/petrelfs/zhangdi1/miniforge3/envs/internvl/lib/python3.9/site-packages/gradio/queueing.py", line 219, in gather_event_data
    data, client_awake = await self.get_message(event, timeout=receive_timeout)
  File "/mnt/petrelfs/zhangdi1/miniforge3/envs/internvl/lib/python3.9/site-packages/gradio/queueing.py", line 448, in get_message
    return PredictBody(**data), True
  File "/mnt/petrelfs/zhangdi1/miniforge3/envs/internvl/lib/python3.9/site-packages/pydantic/main.py", line 176, in __init__
    self.__pydantic_validator__.validate_python(data, self_instance=self)
pydantic_core._pydantic_core.ValidationError: 1 validation error for PredictBody
event_id
  Field required [type=missing, input_value={'data': [], 'event_data'...on_hash': 'k99p9mnm1he'}, input_type=dict]
    For further information visit https://errors.pydantic.dev/2.7/v/missing
2024-06-05 15:41:56 | ERROR | asyncio | Task exception was never retrieved
future: <Task finished name='cwew1l7pn2u_11' coro=<Queue.process_events() done, defined at /mnt/petrelfs/zhangdi1/miniforge3/envs/internvl/lib/python3.9/site-packages/gradio/queueing.py:342> exception=1 validation error for PredictBody
event_id
  Field required [type=missing, input_value={'data': [], 'event_data'...on_hash': 'cwew1l7pn2u'}, input_type=dict]
    For further information visit https://errors.pydantic.dev/2.7/v/missing>
Traceback (most recent call last):
  File "/mnt/petrelfs/zhangdi1/miniforge3/envs/internvl/lib/python3.9/site-packages/gradio/queueing.py", line 346, in process_events
    client_awake = await self.gather_event_data(event)
  File "/mnt/petrelfs/zhangdi1/miniforge3/envs/internvl/lib/python3.9/site-packages/gradio/queueing.py", line 219, in gather_event_data
    data, client_awake = await self.get_message(event, timeout=receive_timeout)
  File "/mnt/petrelfs/zhangdi1/miniforge3/envs/internvl/lib/python3.9/site-packages/gradio/queueing.py", line 448, in get_message
    return PredictBody(**data), True
  File "/mnt/petrelfs/zhangdi1/miniforge3/envs/internvl/lib/python3.9/site-packages/pydantic/main.py", line 176, in __init__
    self.__pydantic_validator__.validate_python(data, self_instance=self)
pydantic_core._pydantic_core.ValidationError: 1 validation error for PredictBody
event_id
  Field required [type=missing, input_value={'data': [], 'event_data'...on_hash': 'cwew1l7pn2u'}, input_type=dict]
    For further information visit https://errors.pydantic.dev/2.7/v/missing
2024-06-05 15:41:58 | ERROR | asyncio | Task exception was never retrieved
future: <Task finished name='gvc80a7zcn_11' coro=<Queue.process_events() done, defined at /mnt/petrelfs/zhangdi1/miniforge3/envs/internvl/lib/python3.9/site-packages/gradio/queueing.py:342> exception=1 validation error for PredictBody
event_id
  Field required [type=missing, input_value={'data': [], 'event_data'...ion_hash': 'gvc80a7zcn'}, input_type=dict]
    For further information visit https://errors.pydantic.dev/2.7/v/missing>
Traceback (most recent call last):
  File "/mnt/petrelfs/zhangdi1/miniforge3/envs/internvl/lib/python3.9/site-packages/gradio/queueing.py", line 346, in process_events
    client_awake = await self.gather_event_data(event)
  File "/mnt/petrelfs/zhangdi1/miniforge3/envs/internvl/lib/python3.9/site-packages/gradio/queueing.py", line 219, in gather_event_data
    data, client_awake = await self.get_message(event, timeout=receive_timeout)
  File "/mnt/petrelfs/zhangdi1/miniforge3/envs/internvl/lib/python3.9/site-packages/gradio/queueing.py", line 448, in get_message
    return PredictBody(**data), True
  File "/mnt/petrelfs/zhangdi1/miniforge3/envs/internvl/lib/python3.9/site-packages/pydantic/main.py", line 176, in __init__
    self.__pydantic_validator__.validate_python(data, self_instance=self)
pydantic_core._pydantic_core.ValidationError: 1 validation error for PredictBody
event_id
  Field required [type=missing, input_value={'data': [], 'event_data'...ion_hash': 'gvc80a7zcn'}, input_type=dict]
    For further information visit https://errors.pydantic.dev/2.7/v/missing
slurmstepd: error: *** JOB 3528886 ON SH-IDC1-10-140-24-69 CANCELLED AT 2024-06-05T15:42:47 ***
